<?xml version="1.0"?>
<!-- created with Phobos 1.0.1 "Capricious Choutengan" -->
  <robot name="ER210">

    <link name="base_link">
      <inertial>
        <origin xyz="-0.056 0.01 -0.58" rpy="0 0 0"/>
        <mass value="130.0"/>
        <inertia ixx="7.69999" ixy="-0.005" ixz="0.00014" iyy="5.30001" iyz="-0.002" izz="4.3"/>
      </inertial>
      <visual name="visual_0_base_link">
        <origin xyz="0 0 0" rpy="0 0 0"/>
        <geometry>
          <mesh filename=".\stl\Base_Link.stl" scale="1.0 1.0 1.0"/>
        </geometry>
        <material name="mat_0"/>
      </visual>
      <collision name="collision_0_base_link">
        <origin xyz="0 0 0" rpy="0 0 0"/>
        <geometry>
          <mesh filename=".\stl\Base_Link.stl" scale="1.0 1.0 1.0"/>
        </geometry>
      </collision>
    </link>

    <link name="link_1">
      <inertial>
        <origin xyz="0.05 0.0045 -0.16" rpy="0 0 0"/>
        <mass value="200.0"/>
        <inertia ixx="11.85004" ixy="-2.23176" ixz="2.28166" iyy="12.60754" iyz="2.7576" izz="11.74242"/>
      </inertial>
      <visual name="visual_0_link_1">
        <origin xyz="0 0 0" rpy="0 0 0"/>
        <geometry>
          <mesh filename=".\stl\Balancer.stl" scale="1.0 1.0 1.0"/>
        </geometry>
        <material name="mat_1a"/>
      </visual>
      <visual name="visual_1_link_1">
        <origin xyz="0 0.001 0" rpy="0 0 0"/>
        <geometry>
          <mesh filename=".\stl\Motor_1.stl" scale="1.0 1.0 1.0"/>
        </geometry>
        <material name="mat_1b"/>
      </visual>
      <visual name="visual_2_link_1">
        <origin xyz="0 0 0" rpy="0 0 0"/>
        <geometry>
          <mesh filename=".\stl\Link_1.stl" scale="1.0 1.0 1.0"/>
        </geometry>
        <material name="mat_1"/>
      </visual>
      <collision name="collision_0_link_1">
        <origin xyz="0 0 0" rpy="0 0 0"/>
        <geometry>
          <mesh filename=".\stl\Link_1.stl" scale="1.0 1.0 1.0"/>
        </geometry>
      </collision>
    </link>

    <link name="link_2">
      <inertial>
        <origin xyz="0.031 0.18 0.52" rpy="0 0 0"/>
        <mass value="87.0"/>
        <inertia ixx="11.99999" ixy="0.00046" ixz="0.0109" iyy="11.98025" iyz="-0.4672" izz="0.94976"/>
      </inertial>
      <visual name="visual_0_link_2">
        <origin xyz="0 0 0" rpy="0 0 0"/>
        <geometry>
          <mesh filename=".\stl\Link_2.stl" scale="1.0 1.0 1.0"/>
        </geometry>
        <material name="mat_2"/>
      </visual>
      <collision name="collision_0_link_2">
        <origin xyz="0 0 0" rpy="0 0 0"/>
        <geometry>
          <mesh filename=".\stl\Link_2.stl" scale="1.0 1.0 1.0"/>
        </geometry>
      </collision>
    </link>

    <link name="link_3">
      <inertial>
        <origin xyz="0.3 0.0045 0.15" rpy="0 0 0"/>
        <mass value="120.0"/>
        <inertia ixx="2.26096" ixy="-0.05628" ixz="-1.75076" iyy="14.98759" iyz="0.10296" izz="13.75144"/>
      </inertial>
      <visual name="visual_0_link_3">
        <origin xyz="0 0 0" rpy="0 0 0"/>
        <geometry>
          <mesh filename=".\stl\Motor_3.stl" scale="1.0 1.0 1.0"/>
        </geometry>
        <material name="mat_3a"/>
      </visual>
      <visual name="visual_1_link_3">
        <origin xyz="0 0 0" rpy="0 0 0"/>
        <geometry>
          <mesh filename=".\stl\Link_3.stl" scale="1.0 1.0 1.0"/>
        </geometry>
        <material name="mat_3"/>
      </visual>
      <collision name="collision_0_link_3">
        <origin xyz="0 0 0" rpy="0 0 0"/>
        <geometry>
          <mesh filename=".\stl\Link_3.stl" scale="1.0 1.0 1.0"/>
        </geometry>
      </collision>
    </link>

    <link name="link_4">
      <inertial>
        <origin xyz="1.1 -0.0045 1e-05" rpy="0 0 0"/>
        <mass value="5.5"/>
        <inertia ixx="0.01423" ixy="0" ixz="0.00287" iyy="0.05099" iyz="8e-05" izz="0.04978"/>
      </inertial>
      <visual name="visual_0_link_4">
        <origin xyz="0 0 0" rpy="0 0 0"/>
        <geometry>
          <mesh filename=".\stl\Link_4.stl" scale="1.0 1.0 1.0"/>
        </geometry>
        <material name="mat_4"/>
      </visual>
      <collision name="collision_0_link_4">
        <origin xyz="0 0 0" rpy="0 0 0"/>
        <geometry>
          <mesh filename=".\stl\Link_4.stl" scale="1.0 1.0 1.0"/>
        </geometry>
      </collision>
    </link>

    <link name="link_5">
      <inertial>
        <origin xyz="0.057 -0.033 8e-05" rpy="0 0 0"/>
        <mass value="13.0"/>
        <inertia ixx="0.12696" ixy="-0.00217" ixz="0.0168" iyy="0.14384" iyz="-0.01577" izz="0.0872"/>
      </inertial>
      <visual name="visual_0_link_5">
        <origin xyz="0 0 0" rpy="0 0 0"/>
        <geometry>
          <mesh filename=".\stl\Link_5.stl" scale="1.0 1.0 1.0"/>
        </geometry>
        <material name="mat_5"/>
      </visual>
      <collision name="collision_0_link_5">
        <origin xyz="0 0 0" rpy="0 0 0"/>
        <geometry>
          <mesh filename=".\stl\Link_5.stl" scale="1.0 1.0 1.0"/>
        </geometry>
      </collision>
    </link>

    <link name="link_6">
      <inertial>
        <origin xyz="-0.015 0.00035 -7e-05" rpy="0 0 0"/>
        <mass value="0.58"/>
        <inertia ixx="0.0018" ixy="0" ixz="0" iyy="0.0009" iyz="0" izz="0.00093"/>
      </inertial>
      <visual name="visual_0_link_6">
        <origin xyz="0 0 0" rpy="0 0 0"/>
        <geometry>
          <mesh filename=".\stl\Link_6.stl" scale="1.0 1.0 1.0"/>
        </geometry>
        <material name="mat_6"/>
      </visual>
      <collision name="collision_0_link_6">
        <origin xyz="0 0 0" rpy="0 0 0"/>
        <geometry>
          <mesh filename=".\stl\Link_6.stl" scale="1.0 1.0 1.0"/>
        </geometry>
      </collision>
    </link>

    <joint name="joint_1" type="revolute">
      <origin xyz="0 0 0" rpy="0 0 0"/>
      <parent link="base_link"/>
      <child link="link_1"/>
      <axis xyz="0 0 1.0"/>
      <limit lower="-3.14" upper="3.14" effort="0" velocity="0"/>
    </joint>

    <joint name="joint_2" type="revolute">
      <origin xyz="0.305 0 0" rpy="0 0 0"/>
      <parent link="link_1"/>
      <child link="link_2"/>
      <axis xyz="0 1.0 0"/>
      <limit lower="-3.14" upper="3.14" effort="0" velocity="0"/>
    </joint>

    <joint name="joint_3" type="revolute">
      <origin xyz="0 0 1.11" rpy="0 0 0"/>
      <parent link="link_2"/>
      <child link="link_3"/>
      <axis xyz="0 1.0 0"/>
      <limit lower="-3.14" upper="3.14" effort="0" velocity="0"/>
    </joint>

    <joint name="joint_4" type="revolute">
      <origin xyz="0 0 0.2" rpy="0 0 0"/>
      <parent link="link_3"/>
      <child link="link_4"/>
      <axis xyz="1.0 0 0"/>
      <limit lower="-3.14" upper="3.14" effort="0" velocity="0"/>
    </joint>

    <joint name="joint_5" type="revolute">
      <origin xyz="1.26 0 0" rpy="0 0 0"/>
      <parent link="link_4"/>
      <child link="link_5"/>
      <axis xyz="0 1.0 0"/>
      <limit lower="-3.14" upper="3.14" effort="0" velocity="0"/>
    </joint>

    <joint name="joint_6" type="revolute">
      <origin xyz="0.2565 0 0" rpy="0 0 0"/>
      <parent link="link_5"/>
      <child link="link_6"/>
      <axis xyz="1.0 0 0"/>
      <limit lower="-3.14" upper="3.14" effort="0" velocity="0"/>
    </joint>

    <material name="mat_0">
      <color rgba="1.0 0 0 1.0"/>
    </material>

    <material name="mat_1">
      <color rgba="1.0 0 0 1.0"/>
    </material>

    <material name="mat_1a">
      <color rgba="0 0 0.6 1.0"/>
    </material>

    <material name="mat_1b">
      <color rgba="0.2 0.2 0.2 1.0"/>
    </material>

    <material name="mat_2">
      <color rgba="1.0 0 0 1.0"/>
    </material>

    <material name="mat_3">
      <color rgba="1.0 0 0 1.0"/>
    </material>

    <material name="mat_3a">
      <color rgba="0.1 0.1 0.1 1.0"/>
    </material>

    <material name="mat_4">
      <color rgba="1.0 0 0 1.0"/>
    </material>

    <material name="mat_5">
      <color rgba="1.0 0 0 1.0"/>
    </material>

    <material name="mat_6">
      <color rgba="0.9 0.9 0.9 1.0"/>
    </material>

  </robot>
